Traceback (most recent call last):
  File "/home/rp/DeepLearning/yolov7-main/utils/google_utils.py", line 26, in attempt_download
    assets = [x['name'] for x in response['assets']]  # release assets
KeyError: 'assets'
During handling of the above exception, another exception occurred:
Traceback (most recent call last):
  File "/home/rp/Softwares/anaconda3/envs/dyh/lib/python3.8/contextlib.py", line 131, in __exit__
    self.gen.throw(type, value, traceback)
  File "/home/rp/DeepLearning/yolov7-main/utils/torch_utils.py", line 34, in torch_distributed_zero_first
    yield
  File "/home/rp/DeepLearning/yolov7-main/train.py", line 86, in train
    attempt_download(weights)  # download if not found locally
  File "/home/rp/DeepLearning/yolov7-main/utils/google_utils.py", line 31, in attempt_download
    tag = subprocess.check_output('git tag', shell=True).decode().split()[-1]
  File "/home/rp/Softwares/anaconda3/envs/dyh/lib/python3.8/subprocess.py", line 415, in check_output
    return run(*popenargs, stdout=PIPE, timeout=timeout, check=True,
  File "/home/rp/Softwares/anaconda3/envs/dyh/lib/python3.8/subprocess.py", line 516, in run
    raise CalledProcessError(retcode, process.args,
subprocess.CalledProcessError: Command 'git tag' returned non-zero exit status 128.